<?xml version="1.0" ?>
<robot name="simpledog_rf_leg" xmlns:xacro="http://ros.org/wiki/xacro">
  <link
    name="base_link">
    <inertial>
      <origin
        xyz="2.919E-17 -4.8141E-17 9.4163E-19"
        rpy="0 0 0" />
      <mass
        value="15.238" />
      <inertia
        ixx="0.74932"
        ixy="-1.2062E-17"
        ixz="-2.0602E-16"
        iyy="2.3017"
        iyz="-3.8366E-17"
        izz="2.9675" />
    </inertial>
  </link>
  <link
    name="front_right_1_Link">
    <inertial>
      <origin
        xyz="9.7104E-17 0.012793 1.6653E-16"
        rpy="0 0 0" />
      <mass
        value="1.1709" />
      <inertia
        ixx="0.001719"
        ixy="-5.88E-19"
        ixz="-1.7779E-19"
        iyy="0.0013167"
        iyz="-2.0543E-19"
        izz="0.0021511" />
    </inertial>
  </link>
  <joint
    name="front_right_1_joint"
    type="revolute">
    <origin
      xyz="0.4 -0.175 0"
      rpy="1.5708 1.5708 -1.5708" />
    <parent
      link="base_link" />
    <child
      link="front_right_1_Link" />
    <axis
      xyz="0 0 1" />
      <limit
      effort="100"
      velocity="10"
      lower="-3.0"
      upper="3.0"/>
  </joint>
  <link
    name="front_right_2_Link">
    <inertial>
      <origin
        xyz="0.11432 -5.5511E-17 0.05942"
        rpy="0 0 0" />
      <mass
        value="1.3902" />
      <inertia
        ixx="0.0030209"
        ixy="-4.0905E-18"
        ixz="-8.1586E-10"
        iyy="0.026875"
        iyz="2.3399E-19"
        izz="0.028484" />
    </inertial>
  </link>
  <joint
    name="front_right_2_joint"
    type="revolute">
    <origin
      xyz="0 0 0"
      rpy="-1.5708 0 0" />
    <parent
      link="front_right_1_Link" />
    <child
      link="front_right_2_Link" />
    <axis
      xyz="0 0 1" />
      <limit
      effort="100"
      velocity="10"
      lower="-3.0"
      upper="3.0"/>
  </joint>
  <link
    name="front_right_3_Link">
    <inertial>
      <origin
        xyz="0.087821 6.7221E-06 -0.016729"
        rpy="0 0 0" />
      <mass
        value="1.3523" />
      <inertia
        ixx="0.00053022"
        ixy="-9.5809E-07"
        ixz="-0.00020532"
        iyy="0.0091429"
        iyz="1.6437E-08"
        izz="0.0093381" />
    </inertial>
  </link>
  <joint
    name="front_right_3_joint"
    type="revolute">
    <origin
      xyz="0.249999996334044 0 0.114419764295838"
      rpy="0 0 0" />
    <parent
      link="front_right_2_Link" />
    <child
      link="front_right_3_Link" />
    <axis
      xyz="0 0 1" />
      <limit
      effort="100"
      velocity="10"
      lower="-3.0"
      upper="3.0"/>
  </joint>
  <link
    name="rf_foot_Link">
    <inertial>
      <origin
        xyz="0.017825 0 0"
        rpy="0 0 0" />
      <mass
        value="0.055619" />
      <inertia
        ixx="1.655E-05"
        ixy="2.2089E-21"
        ixz="-1.1638E-21"
        iyy="1.2322E-05"
        iyz="-2.0835E-21"
        izz="1.257E-05" />
    </inertial>
  </link>
  <joint
    name="rf_foot_joint"
    type="fixed">
    <origin
      xyz="0.25 0 -0.0149999996816874"
      rpy="-0.00020601381558494 5.03069808033274E-17 -4.99600361081321E-16" />
    <parent
      link="front_right_3_Link" />
    <child
      link="rf_foot_Link" />
    <axis
      xyz="0 0 0" />
  </joint>


</robot>
