<?xml version="1.0" ?>
<robot name="simpledog_lf_leg" xmlns:xacro="http://ros.org/wiki/xacro">
  <link
    name="base_link">
    <inertial>
      <origin
        xyz="2.919E-17 -4.8141E-17 9.4163E-19"
        rpy="0 0 0" />
      <mass
        value="15.238" />
      <inertia
        ixx="0.74932"
        ixy="-1.2062E-17"
        ixz="-2.0602E-16"
        iyy="2.3017"
        iyz="-3.8366E-17"
        izz="2.9675" />
    </inertial>
  </link>
  <link
    name="front_left_1_Link">
    <inertial>
      <origin
        xyz="1.7015E-17 0.012793 -0.00023552"
        rpy="0 0 0" />
      <mass
        value="1.1709" />
      <inertia
        ixx="0.001719"
        ixy="2.9302E-20"
        ixz="-1.6433E-19"
        iyy="0.0013167"
        iyz="-7.6795E-20"
        izz="0.0021511" />
    </inertial>
  </link>
  <joint
    name="front_left_1_joint"
    type="revolute">
    <origin
      xyz="0.400 0.175 0"
      rpy="1.57079632679453 1.57051603921301 1.57079632679453" />
    <parent
      link="base_link" />
    <child
      link="front_left_1_Link" />
    <axis
      xyz="0 0 1" />
      <limit
      effort="100"
      velocity="10"
      lower="-3.0"
      upper="3.0"/>
  </joint>
  <link
    name="front_left_2_Link">
    <inertial>
      <origin
        xyz="0.11439 0.00028184 0.05942"
        rpy="0 0 0" />
      <mass
        value="1.3902" />
      <inertia
        ixx="0.0030209"
        ixy="-5.6504E-20"
        ixz="2.8413E-18"
        iyy="0.026875"
        iyz="1.5349E-06"
        izz="0.028484" />
    </inertial>
  </link>
  <joint
    name="front_left_2_joint"
    type="revolute">
    <origin
      xyz="0 0 0"
      rpy="-1.5708 0 0" />
    <parent
      link="front_left_1_Link" />
    <child
      link="front_left_2_Link" />
    <axis
      xyz="0 0 1" />
      <limit
      effort="100"
      velocity="10"
      lower="-3.0"
      upper="3.0"/>
  </joint>
  <link
    name="front_left_3_Link">
    <inertial>
      <origin
        xyz="0.087825 1.529E-05 -0.016708"
        rpy="0 0 0" />
      <mass
        value="1.3523" />
      <inertia
        ixx="0.00053032"
        ixy="-8.5291E-07"
        ixz="-0.00020744"
        iyy="0.0091429"
        iyz="-8.3738E-08"
        izz="0.009338" />
    </inertial>
  </link>
  <joint
    name="front_left_3_joint"
    type="revolute">
    <origin
      xyz="0.250069171339977 0.000334332414087979 0.11441948932032"
      rpy="0 0 0" />
    <parent
      link="front_left_2_Link" />
    <child
      link="front_left_3_Link" />
    <axis
      xyz="0 0 1" />
      <limit
      effort="100"
      velocity="10"
      lower="-3.0"
      upper="3.0"/>
  </joint>
  <link
    name="lf_foot_Link">
    <inertial>
      <origin
        xyz="0.0178251114319979 0 0"
        rpy="0 0 0" />
      <mass
        value="0.0556193699314689" />
      <inertia
        ixx="1.65498601680364E-05"
        ixy="-1.00565663974796E-21"
        ixz="1.3524403015242E-22"
        iyy="1.23221647613412E-05"
        iyz="-3.56241096455504E-11"
        izz="1.25699738250509E-05" />
    </inertial>
  </link>
  <joint
    name="lf_foot_joint"
    type="fixed">
    <origin
      xyz="0.250003601978058 0 -0.0149398452771417"
      rpy="0 0 0" />
    <parent
      link="front_left_3_Link" />
    <child
      link="lf_foot_Link" />
    <axis
      xyz="0 0 0" />
  </joint>

</robot>
