<?xml version="1.0" ?>
<robot name="simpledog" xmlns:xacro="http://ros.org/wiki/xacro">
  <link
    name="base_link">
    <inertial>
      <origin
        xyz="2.919E-17 -4.8141E-17 9.4163E-19"
        rpy="0 0 0" />
      <mass
        value="15.238" />
      <inertia
        ixx="0.74932"
        ixy="-1.2062E-17"
        ixz="-2.0602E-16"
        iyy="2.3017"
        iyz="-3.8366E-17"
        izz="2.9675" />
    </inertial>
  </link>
  <link
    name="front_left_1_Link">
    <inertial>
      <origin
        xyz="1.7015E-17 0.012793 -0.00023552"
        rpy="0 0 0" />
      <mass
        value="1.1709" />
      <inertia
        ixx="0.001719"
        ixy="2.9302E-20"
        ixz="-1.6433E-19"
        iyy="0.0013167"
        iyz="-7.6795E-20"
        izz="0.0021511" />
    </inertial>
  </link>
  <joint
    name="front_left_1_joint"
    type="revolute">
    <origin
      xyz="0.400 0.175 0"
      rpy="1.57079632679453 1.57051603921301 1.57079632679453" />
    <parent
      link="base_link" />
    <child
      link="front_left_1_Link" />
    <axis
      xyz="0 0 1" />
      <limit
      effort="100"
      velocity="10"
      lower="-3.0"
      upper="3.0"/>
  </joint>
  <link
    name="front_left_2_Link">
    <inertial>
      <origin
        xyz="0.11439 0.00028184 0.05942"
        rpy="0 0 0" />
      <mass
        value="1.3902" />
      <inertia
        ixx="0.0030209"
        ixy="-5.6504E-20"
        ixz="2.8413E-18"
        iyy="0.026875"
        iyz="1.5349E-06"
        izz="0.028484" />
    </inertial>
  </link>
  <joint
    name="front_left_2_joint"
    type="revolute">
    <origin
      xyz="0 0 0"
      rpy="-1.5708 0 0" />
    <parent
      link="front_left_1_Link" />
    <child
      link="front_left_2_Link" />
    <axis
      xyz="0 0 1" />
      <limit
      effort="100"
      velocity="10"
      lower="-3.0"
      upper="3.0"/>
  </joint>
  <link
    name="front_left_3_Link">
    <inertial>
      <origin
        xyz="0.087825 1.529E-05 -0.016708"
        rpy="0 0 0" />
      <mass
        value="1.3523" />
      <inertia
        ixx="0.00053032"
        ixy="-8.5291E-07"
        ixz="-0.00020744"
        iyy="0.0091429"
        iyz="-8.3738E-08"
        izz="0.009338" />
    </inertial>
  </link>
  <joint
    name="front_left_3_joint"
    type="revolute">
    <origin
      xyz="0.250069171339977 0.000334332414087979 0.11441948932032"
      rpy="0 0 0" />
    <parent
      link="front_left_2_Link" />
    <child
      link="front_left_3_Link" />
    <axis
      xyz="0 0 1" />
      <limit
      effort="100"
      velocity="10"
      lower="-3.0"
      upper="3.0"/>
  </joint>
  <link
    name="lf_foot_Link">
    <inertial>
      <origin
        xyz="0.0178251114319979 0 0"
        rpy="0 0 0" />
      <mass
        value="0.0556193699314689" />
      <inertia
        ixx="1.65498601680364E-05"
        ixy="-1.00565663974796E-21"
        ixz="1.3524403015242E-22"
        iyy="1.23221647613412E-05"
        iyz="-3.56241096455504E-11"
        izz="1.25699738250509E-05" />
    </inertial>
  </link>
  <joint
    name="lf_foot_joint"
    type="fixed">
    <origin
      xyz="0.250003601978058 0 -0.0149398452771417"
      rpy="0 0 0" />
    <parent
      link="front_left_3_Link" />
    <child
      link="lf_foot_Link" />
    <axis
      xyz="0 0 0" />
  </joint>
  <link
    name="front_right_1_Link">
    <inertial>
      <origin
        xyz="9.7104E-17 0.012793 1.6653E-16"
        rpy="0 0 0" />
      <mass
        value="1.1709" />
      <inertia
        ixx="0.001719"
        ixy="-5.88E-19"
        ixz="-1.7779E-19"
        iyy="0.0013167"
        iyz="-2.0543E-19"
        izz="0.0021511" />
    </inertial>
  </link>
  <joint
    name="front_right_1_joint"
    type="revolute">
    <origin
      xyz="0.4 -0.175 0"
      rpy="1.5708 1.5708 -1.5708" />
    <parent
      link="base_link" />
    <child
      link="front_right_1_Link" />
    <axis
      xyz="0 0 1" />
      <limit
      effort="100"
      velocity="10"
      lower="-3.0"
      upper="3.0"/>
  </joint>
  <link
    name="front_right_2_Link">
    <inertial>
      <origin
        xyz="0.11432 -5.5511E-17 0.05942"
        rpy="0 0 0" />
      <mass
        value="1.3902" />
      <inertia
        ixx="0.0030209"
        ixy="-4.0905E-18"
        ixz="-8.1586E-10"
        iyy="0.026875"
        iyz="2.3399E-19"
        izz="0.028484" />
    </inertial>
  </link>
  <joint
    name="front_right_2_joint"
    type="revolute">
    <origin
      xyz="0 0 0"
      rpy="-1.5708 0 0" />
    <parent
      link="front_right_1_Link" />
    <child
      link="front_right_2_Link" />
    <axis
      xyz="0 0 1" />
      <limit
      effort="100"
      velocity="10"
      lower="-3.0"
      upper="3.0"/>
  </joint>
  <link
    name="front_right_3_Link">
    <inertial>
      <origin
        xyz="0.087821 6.7221E-06 -0.016729"
        rpy="0 0 0" />
      <mass
        value="1.3523" />
      <inertia
        ixx="0.00053022"
        ixy="-9.5809E-07"
        ixz="-0.00020532"
        iyy="0.0091429"
        iyz="1.6437E-08"
        izz="0.0093381" />
    </inertial>
  </link>
  <joint
    name="front_right_3_joint"
    type="revolute">
    <origin
      xyz="0.249999996334044 0 0.114419764295838"
      rpy="0 0 0" />
    <parent
      link="front_right_2_Link" />
    <child
      link="front_right_3_Link" />
    <axis
      xyz="0 0 1" />
      <limit
      effort="100"
      velocity="10"
      lower="-3.0"
      upper="3.0"/>
  </joint>
  <link
    name="rf_foot_Link">
    <inertial>
      <origin
        xyz="0.017825 0 0"
        rpy="0 0 0" />
      <mass
        value="0.055619" />
      <inertia
        ixx="1.655E-05"
        ixy="2.2089E-21"
        ixz="-1.1638E-21"
        iyy="1.2322E-05"
        iyz="-2.0835E-21"
        izz="1.257E-05" />
    </inertial>
  </link>
  <joint
    name="rf_foot_joint"
    type="fixed">
    <origin
      xyz="0.25 0 -0.0149999996816874"
      rpy="-0.00020601381558494 5.03069808033274E-17 -4.99600361081321E-16" />
    <parent
      link="front_right_3_Link" />
    <child
      link="rf_foot_Link" />
    <axis
      xyz="0 0 0" />
  </joint>
  <link
    name="rear_left_1_Link">
    <inertial>
      <origin
        xyz="5.7896E-17 0.012793 2.7756E-16"
        rpy="0 0 0" />
      <mass
        value="1.1709" />
      <inertia
        ixx="0.001719"
        ixy="-2.0371E-19"
        ixz="5.3128E-21"
        iyy="0.0013167"
        iyz="-3.3901E-19"
        izz="0.0021511" />
    </inertial>
  </link>
  <joint
    name="rear_left_1_joint"
    type="revolute">
    <origin
      xyz="-0.4 0.175 0"
      rpy="1.57079632679488 1.56519932988528 1.57079632679488" />
    <parent
      link="base_link" />
    <child
      link="rear_left_1_Link" />
    <axis
      xyz="0 0 1" />
      <limit
      effort="100"
      velocity="10"
      lower="-3.0"
      upper="3.0"/>
  </joint>
  <link
    name="rear_left_2_Link">
    <inertial>
      <origin
        xyz="0.11432 0 0.05942"
        rpy="0 0 0" />
      <mass
        value="1.3902" />
      <inertia
        ixx="0.0030209"
        ixy="-1.8526E-18"
        ixz="2.5242E-19"
        iyy="0.026875"
        iyz="3.7608E-19"
        izz="0.028484" />
    </inertial>
  </link>
  <joint
    name="rear_left_2_joint"
    type="revolute">
    <origin
      xyz="0 0 0"
      rpy="-1.5707963267949 0 0" />
    <parent
      link="rear_left_1_Link" />
    <child
      link="rear_left_2_Link" />
    <axis
      xyz="0 0 1" />
      <limit
      effort="100"
      velocity="10"
      lower="-3.0"
      upper="3.0"/>
  </joint>
  <link
    name="rear_left_3_Link">
    <inertial>
      <origin
        xyz="0.087821 5.7424E-05 -0.016729"
        rpy="0 0 0" />
      <mass
        value="1.3523" />
      <inertia
        ixx="0.00053022"
        ixy="-3.3581E-07"
        ixz="-0.00020532"
        iyy="0.0091429"
        iyz="-5.7512E-07"
        izz="0.0093381" />
    </inertial>
  </link>
  <joint
    name="rear_left_3_joint"
    type="revolute">
    <origin
      xyz="0.25 0 0.114419756285561"
      rpy="0 0 0" />
    <parent
      link="rear_left_2_Link" />
    <child
      link="rear_left_3_Link" />
    <axis
      xyz="0 0 1" />
      <limit
      effort="100"
      velocity="10"
      lower="-3.0"
      upper="3.0"/>
  </joint>
  <link
    name="rh_foot_Link">
    <inertial>
      <origin
        xyz="0.017825 -1.1102E-16 5.5511E-17"
        rpy="0 0 0" />
      <mass
        value="0.055619" />
      <inertia
        ixx="1.655E-05"
        ixy="3.2567E-22"
        ixz="-9.7111E-22"
        iyy="1.2322E-05"
        iyz="5.4896E-20"
        izz="1.257E-05" />
    </inertial>
  </link>
  <joint
    name="rh_foot_joint"
    type="fixed">
    <origin
      xyz="0.24742286767759 0.000379574544590811 -0.015"
      rpy="0 0 0" />
    <parent
      link="rear_left_3_Link" />
    <child
      link="rh_foot_Link" />
    <axis
      xyz="0 0 0" />
  </joint>
  <link
    name="rear_right_1_Link">
    <inertial>
      <origin
        xyz="-6.2968E-06 0.012793 0.0003022"
        rpy="0 0 0" />
      <mass
        value="1.1709" />
      <inertia
        ixx="0.001719"
        ixy="1.9803E-07"
        ixz="-1.4315E-19"
        iyy="0.0013167"
        iyz="-1.2614E-19"
        izz="0.0021511" />
    </inertial>
  </link>
  <joint
    name="rear_right_1_joint"
    type="revolute">
    <origin
      xyz="-0.4 -0.175 0"
      rpy="1.5708 1.5708 -1.5708" />
    <parent
      link="base_link" />
    <child
      link="rear_right_1_Link" />
    <axis
      xyz="0 0 1" />
      <limit
      effort="100"
      velocity="10"
      lower="-3.0"
      upper="3.0"/>
  </joint>
  <link
    name="rear_right_2_Link">
    <inertial>
      <origin
        xyz="0.11443 -8.407E-05 0.05942"
        rpy="0 0 0" />
      <mass
        value="1.3902" />
      <inertia
        ixx="0.0030209"
        ixy="-4.1489E-12"
        ixz="-1.2337E-09"
        iyy="0.026876"
        iyz="5.4085E-06"
        izz="0.028484" />
    </inertial>
  </link>
  <joint
    name="rear_right_2_joint"
    type="revolute">
    <origin
      xyz="0 0 0"
      rpy="-1.5708 0 0" />
    <parent
      link="rear_right_1_Link" />
    <child
      link="rear_right_2_Link" />
    <axis
      xyz="0 0 1" />
      <limit
      effort="100"
      velocity="10"
      lower="-3.0"
      upper="3.0"/>
  </joint>
  <link
    name="rear_right_3_Link">
    <inertial>
      <origin
        xyz="0.087821 6.0067E-06 -0.016729"
        rpy="0 0 0" />
      <mass
        value="1.3523" />
      <inertia
        ixx="0.00053022"
        ixy="-9.6687E-07"
        ixz="-0.00020532"
        iyy="0.0091429"
        iyz="2.4784E-08"
        izz="0.0093381" />
    </inertial>
  </link>
  <joint
    name="rear_right_3_joint"
    type="revolute">
    <origin
      xyz="0.25010358767993 0.0001008844556592 0.114420076111023"
      rpy="0 0 0" />
    <parent
      link="rear_right_2_Link" />
    <child
      link="rear_right_3_Link" />
    <axis
      xyz="0 0 1" />
      <limit
      effort="100"
      velocity="10"
      lower="-3.0"
      upper="3.0"/>
  </joint>
  <link
    name="lh_foot_Link">
    <inertial>
      <origin
        xyz="0.017825 -1.1102E-16 0"
        rpy="0 0 0" />
      <mass
        value="0.055619" />
      <inertia
        ixx="1.655E-05"
        ixy="2.3509E-21"
        ixz="-1.4161E-21"
        iyy="1.2322E-05"
        iyz="6.8491E-22"
        izz="1.257E-05" />
    </inertial>
  </link>
  <joint
    name="lh_foot_joint"
    type="fixed">
    <origin
      xyz="0.24968 0.00033355 -0.015"
      rpy="0 0 0" />
    <parent
      link="rear_right_3_Link" />
    <child
      link="lh_foot_Link" />
    <axis
      xyz="0 0 0" />
  </joint>


</robot>
