<?xml version="1.0" ?>
<robot name="simpledog_lh_leg" xmlns:xacro="http://ros.org/wiki/xacro">
  <link
    name="base_link">
    <inertial>
      <origin
        xyz="2.919E-17 -4.8141E-17 9.4163E-19"
        rpy="0 0 0" />
      <mass
        value="15.238" />
      <inertia
        ixx="0.74932"
        ixy="-1.2062E-17"
        ixz="-2.0602E-16"
        iyy="2.3017"
        iyz="-3.8366E-17"
        izz="2.9675" />
    </inertial>
  </link>
  
  <link
    name="rear_left_1_Link">
    <inertial>
      <origin
        xyz="5.7896E-17 0.012793 2.7756E-16"
        rpy="0 0 0" />
      <mass
        value="1.1709" />
      <inertia
        ixx="0.001719"
        ixy="-2.0371E-19"
        ixz="5.3128E-21"
        iyy="0.0013167"
        iyz="-3.3901E-19"
        izz="0.0021511" />
    </inertial>
  </link>
  <joint
    name="rear_left_1_joint"
    type="revolute">
    <origin
      xyz="-0.4 0.175 0"
      rpy="1.57079632679488 1.56519932988528 1.57079632679488" />
    <parent
      link="base_link" />
    <child
      link="rear_left_1_Link" />
    <axis
      xyz="0 0 1" />
      <limit
      effort="100"
      velocity="10"
      lower="-3.0"
      upper="3.0"/>
  </joint>
  <link
    name="rear_left_2_Link">
    <inertial>
      <origin
        xyz="0.11432 0 0.05942"
        rpy="0 0 0" />
      <mass
        value="1.3902" />
      <inertia
        ixx="0.0030209"
        ixy="-1.8526E-18"
        ixz="2.5242E-19"
        iyy="0.026875"
        iyz="3.7608E-19"
        izz="0.028484" />
    </inertial>
  </link>
  <joint
    name="rear_left_2_joint"
    type="revolute">
    <origin
      xyz="0 0 0"
      rpy="-1.5707963267949 0 0" />
    <parent
      link="rear_left_1_Link" />
    <child
      link="rear_left_2_Link" />
    <axis
      xyz="0 0 1" />
      <limit
      effort="100"
      velocity="10"
      lower="-3.0"
      upper="3.0"/>
  </joint>
  <link
    name="rear_left_3_Link">
    <inertial>
      <origin
        xyz="0.087821 5.7424E-05 -0.016729"
        rpy="0 0 0" />
      <mass
        value="1.3523" />
      <inertia
        ixx="0.00053022"
        ixy="-3.3581E-07"
        ixz="-0.00020532"
        iyy="0.0091429"
        iyz="-5.7512E-07"
        izz="0.0093381" />
    </inertial>
  </link>
  <joint
    name="rear_left_3_joint"
    type="revolute">
    <origin
      xyz="0.25 0 0.114419756285561"
      rpy="0 0 0" />
    <parent
      link="rear_left_2_Link" />
    <child
      link="rear_left_3_Link" />
    <axis
      xyz="0 0 1" />
      <limit
      effort="100"
      velocity="10"
      lower="-3.0"
      upper="3.0"/>
  </joint>
  <link
    name="lh_foot_Link">
    <inertial>
      <origin
        xyz="0.017825 -1.1102E-16 5.5511E-17"
        rpy="0 0 0" />
      <mass
        value="0.055619" />
      <inertia
        ixx="1.655E-05"
        ixy="3.2567E-22"
        ixz="-9.7111E-22"
        iyy="1.2322E-05"
        iyz="5.4896E-20"
        izz="1.257E-05" />
    </inertial>
  </link>
  <joint
    name="lh_foot_joint"
    type="fixed">
    <origin
      xyz="0.24742286767759 0.000379574544590811 -0.015"
      rpy="0 0 0" />
    <parent
      link="rear_left_3_Link" />
    <child
      link="lh_foot_Link" />
    <axis
      xyz="0 0 0" />
  </joint>
 


</robot>
